{"primaryContentSections":[{"kind":"declarations","declarations":[{"tokens":[{"kind":"keyword","text":"func"},{"kind":"text","text":" "},{"kind":"identifier","text":"reject"},{"kind":"text","text":"("},{"kind":"externalParam","text":"with"},{"kind":"text","text":" "},{"kind":"internalParam","text":"error"},{"kind":"text","text":": "},{"kind":"typeIdentifier","identifier":"doc:\/\/cz.csas.app.cshub.test\/documentation\/CSHub_Test\/CSError","preciseIdentifier":"s:10CSHub_Test7CSErrorO","text":"CSError"},{"kind":"text","text":")"}],"languages":["swift"],"platforms":["iOS"]}]},{"kind":"parameters","parameters":[{"name":"error","content":[{"type":"paragraph","inlineContent":[{"type":"text","text":"error value for promise to be rejected with"}]}]}]},{"kind":"content","content":[{"anchor":"discussion","level":2,"type":"heading","text":"Discussion"},{"type":"codeListing","syntax":null,"code":["func obtainNetworkedData(urlString: String) -> Future<Data> {","","    let promise = Promise<Data>","    ⋮","    \/\/ network returns 404 error","    promise.reject(error: .notFoundError)","    ⋮","    return promise","}"]}]}],"schemaVersion":{"major":0,"minor":3,"patch":0},"sections":[],"variants":[{"paths":["\/documentation\/cshub_test\/future\/reject(with:)"],"traits":[{"interfaceLanguage":"swift"}]}],"identifier":{"url":"doc:\/\/cz.csas.app.cshub.test\/documentation\/CSHub_Test\/Future\/reject(with:)","interfaceLanguage":"swift"},"abstract":[{"type":"text","text":"helper function that rejects the previously created and returned "},{"type":"codeVoice","code":"Promise"},{"type":"text","text":" "},{"type":"text","text":"with an error that has been returned by some async call"}],"kind":"symbol","metadata":{"fragments":[{"kind":"keyword","text":"func"},{"kind":"text","text":" "},{"kind":"identifier","text":"reject"},{"kind":"text","text":"("},{"kind":"externalParam","text":"with"},{"kind":"text","text":": "},{"kind":"typeIdentifier","text":"CSError","preciseIdentifier":"s:10CSHub_Test7CSErrorO"},{"kind":"text","text":")"}],"title":"reject(with:)","roleHeading":"Instance Method","role":"symbol","symbolKind":"method","externalID":"s:10CSHub_Test6FutureC6reject4withyAA7CSErrorO_tF","modules":[{"name":"CSHub_Test"}]},"hierarchy":{"paths":[["doc:\/\/cz.csas.app.cshub.test\/documentation\/CSHub_Test","doc:\/\/cz.csas.app.cshub.test\/documentation\/CSHub_Test\/Future"]]},"references":{"doc://cz.csas.app.cshub.test/documentation/CSHub_Test/Future":{"role":"symbol","title":"Future","fragments":[{"kind":"keyword","text":"class"},{"kind":"text","text":" "},{"kind":"identifier","text":"Future"}],"abstract":[{"type":"codeVoice","code":"Future"},{"type":"text","text":" type representing "},{"type":"strong","inlineContent":[{"type":"text","text":"asynchronous return value of the function"}]},{"type":"text","text":" "},{"type":"text","text":"that can be observed later on in the future. returned type will be either success"},{"type":"text","text":" "},{"type":"text","text":"with a value "},{"type":"codeVoice","code":"T"},{"type":"text","text":" or failure with an error "},{"type":"codeVoice","code":"E"}],"identifier":"doc:\/\/cz.csas.app.cshub.test\/documentation\/CSHub_Test\/Future","kind":"symbol","type":"topic","navigatorTitle":[{"kind":"identifier","text":"Future"}],"url":"\/documentation\/cshub_test\/future"},"doc://cz.csas.app.cshub.test/documentation/CSHub_Test":{"role":"collection","title":"CSHub_Test","abstract":[],"identifier":"doc:\/\/cz.csas.app.cshub.test\/documentation\/CSHub_Test","kind":"symbol","type":"topic","url":"\/documentation\/cshub_test"},"doc://cz.csas.app.cshub.test/documentation/CSHub_Test/CSError":{"role":"symbol","title":"CSError","fragments":[{"kind":"keyword","text":"enum"},{"kind":"text","text":" "},{"kind":"identifier","text":"CSError"}],"abstract":[],"identifier":"doc:\/\/cz.csas.app.cshub.test\/documentation\/CSHub_Test\/CSError","kind":"symbol","type":"topic","navigatorTitle":[{"kind":"identifier","text":"CSError"}],"url":"\/documentation\/cshub_test\/cserror"},"doc://cz.csas.app.cshub.test/documentation/CSHub_Test/Future/reject(with:)":{"role":"symbol","title":"reject(with:)","fragments":[{"kind":"keyword","text":"func"},{"kind":"text","text":" "},{"kind":"identifier","text":"reject"},{"kind":"text","text":"("},{"kind":"externalParam","text":"with"},{"kind":"text","text":": "},{"kind":"typeIdentifier","text":"CSError","preciseIdentifier":"s:10CSHub_Test7CSErrorO"},{"kind":"text","text":")"}],"abstract":[{"type":"text","text":"helper function that rejects the previously created and returned "},{"type":"codeVoice","code":"Promise"},{"type":"text","text":" "},{"type":"text","text":"with an error that has been returned by some async call"}],"identifier":"doc:\/\/cz.csas.app.cshub.test\/documentation\/CSHub_Test\/Future\/reject(with:)","kind":"symbol","type":"topic","url":"\/documentation\/cshub_test\/future\/reject(with:)"}}}